2020-04-06 12:38:23,314 ERROR: Exception on /reset_password_request [GET] [in /home/pi/Desktop/microblog/venv/lib/python3.7/site-packages/flask/app.py:1891]
Traceback (most recent call last):
  File "/home/pi/Desktop/microblog/venv/lib/python3.7/site-packages/flask/app.py", line 2446, in wsgi_app
    response = self.full_dispatch_request()
  File "/home/pi/Desktop/microblog/venv/lib/python3.7/site-packages/flask/app.py", line 1951, in full_dispatch_request
    rv = self.handle_user_exception(e)
  File "/home/pi/Desktop/microblog/venv/lib/python3.7/site-packages/flask/app.py", line 1820, in handle_user_exception
    reraise(exc_type, exc_value, tb)
  File "/home/pi/Desktop/microblog/venv/lib/python3.7/site-packages/flask/_compat.py", line 39, in reraise
    raise value
  File "/home/pi/Desktop/microblog/venv/lib/python3.7/site-packages/flask/app.py", line 1949, in full_dispatch_request
    rv = self.dispatch_request()
  File "/home/pi/Desktop/microblog/venv/lib/python3.7/site-packages/flask/app.py", line 1935, in dispatch_request
    return self.view_functions[rule.endpoint](**req.view_args)
  File "/home/pi/Desktop/microblog/app/routes.py", line 106, in reset_password_request
    return render_template('reset_password_request.html', title='Reset Password', form=form)
  File "/home/pi/Desktop/microblog/venv/lib/python3.7/site-packages/flask/templating.py", line 140, in render_template
    ctx.app,
  File "/home/pi/Desktop/microblog/venv/lib/python3.7/site-packages/flask/templating.py", line 120, in _render
    rv = template.render(context)
  File "/home/pi/Desktop/microblog/venv/lib/python3.7/site-packages/jinja2/environment.py", line 1090, in render
    self.environment.handle_exception()
  File "/home/pi/Desktop/microblog/venv/lib/python3.7/site-packages/jinja2/environment.py", line 832, in handle_exception
    reraise(*rewrite_traceback_stack(source=source))
  File "/home/pi/Desktop/microblog/venv/lib/python3.7/site-packages/jinja2/_compat.py", line 28, in reraise
    raise value.with_traceback(tb)
  File "/home/pi/Desktop/microblog/app/templates/reset_password_request.html", line 1, in top-level template code
    {% extends base.html %}
  File "/home/pi/Desktop/microblog/venv/lib/python3.7/site-packages/jinja2/environment.py", line 471, in getattr
    return getattr(obj, attribute)
jinja2.exceptions.UndefinedError: 'base' is undefined
2020-04-06 12:39:29,972 INFO: Microblog startup [in /home/pi/Desktop/microblog/app/__init__.py:47]
2020-04-06 12:40:18,182 ERROR: Exception on /reset_password_request [POST] [in /home/pi/Desktop/microblog/venv/lib/python3.7/site-packages/flask/app.py:1891]
Traceback (most recent call last):
  File "/home/pi/Desktop/microblog/venv/lib/python3.7/site-packages/flask/app.py", line 2446, in wsgi_app
    response = self.full_dispatch_request()
  File "/home/pi/Desktop/microblog/venv/lib/python3.7/site-packages/flask/app.py", line 1951, in full_dispatch_request
    rv = self.handle_user_exception(e)
  File "/home/pi/Desktop/microblog/venv/lib/python3.7/site-packages/flask/app.py", line 1820, in handle_user_exception
    reraise(exc_type, exc_value, tb)
  File "/home/pi/Desktop/microblog/venv/lib/python3.7/site-packages/flask/_compat.py", line 39, in reraise
    raise value
  File "/home/pi/Desktop/microblog/venv/lib/python3.7/site-packages/flask/app.py", line 1949, in full_dispatch_request
    rv = self.dispatch_request()
  File "/home/pi/Desktop/microblog/venv/lib/python3.7/site-packages/flask/app.py", line 1935, in dispatch_request
    return self.view_functions[rule.endpoint](**req.view_args)
  File "/home/pi/Desktop/microblog/app/routes.py", line 103, in reset_password_request
    send_password_reset_email(user)
  File "/home/pi/Desktop/microblog/app/email.py", line 15, in send_password_reset_email
    token = user.get_reset_password_token()
  File "/home/pi/Desktop/microblog/app/models.py", line 63, in get_reset_password_token
    return jwt.encode(
NameError: name 'jwt' is not defined
2020-04-06 12:45:16,037 INFO: Microblog startup [in /home/pi/Desktop/microblog/app/__init__.py:47]
2020-04-06 12:45:56,735 ERROR: Exception on /reset_password/eyJ0eXAiOiJKV1QiLCJhbGciOiJIUzI1NiJ9.eyJyZXNldF9wYXNzd29yZCI6MiwiZXhwIjoxNTg2MTkyMTI1LjkzMTAwOX0.5IpzsYRYwtI-OGGisGRS64imTxQQRX6kx0zA-u2nM60 [GET] [in /home/pi/Desktop/microblog/venv/lib/python3.7/site-packages/flask/app.py:1891]
Traceback (most recent call last):
  File "/home/pi/Desktop/microblog/venv/lib/python3.7/site-packages/flask/app.py", line 2446, in wsgi_app
    response = self.full_dispatch_request()
  File "/home/pi/Desktop/microblog/venv/lib/python3.7/site-packages/flask/app.py", line 1952, in full_dispatch_request
    return self.finalize_request(rv)
  File "/home/pi/Desktop/microblog/venv/lib/python3.7/site-packages/flask/app.py", line 1967, in finalize_request
    response = self.make_response(rv)
  File "/home/pi/Desktop/microblog/venv/lib/python3.7/site-packages/flask/app.py", line 2097, in make_response
    "The view function did not return a valid response. The"
TypeError: The view function did not return a valid response. The function either returned None or ended without a return statement.
2020-04-06 13:20:33,458 ERROR: Exception on /reset_password/eyJ0eXAiOiJKV1QiLCJhbGciOiJIUzI1NiJ9.eyJyZXNldF9wYXNzd29yZCI6MiwiZXhwIjoxNTg2MTkyMTI1LjkzMTAwOX0.5IpzsYRYwtI-OGGisGRS64imTxQQRX6kx0zA-u2nM60 [GET] [in /home/pi/Desktop/microblog/venv/lib/python3.7/site-packages/flask/app.py:1891]
Traceback (most recent call last):
  File "/home/pi/Desktop/microblog/venv/lib/python3.7/site-packages/flask/app.py", line 2446, in wsgi_app
    response = self.full_dispatch_request()
  File "/home/pi/Desktop/microblog/venv/lib/python3.7/site-packages/flask/app.py", line 1952, in full_dispatch_request
    return self.finalize_request(rv)
  File "/home/pi/Desktop/microblog/venv/lib/python3.7/site-packages/flask/app.py", line 1967, in finalize_request
    response = self.make_response(rv)
  File "/home/pi/Desktop/microblog/venv/lib/python3.7/site-packages/flask/app.py", line 2097, in make_response
    "The view function did not return a valid response. The"
TypeError: The view function did not return a valid response. The function either returned None or ended without a return statement.
2020-04-06 13:23:28,352 INFO: Microblog startup [in /home/pi/Desktop/microblog/app/__init__.py:47]
