2020-04-01 16:23:32,186 ERROR: Exception on / [GET] [in /home/pi/Desktop/microblog/venv/lib/python3.7/site-packages/flask/app.py:1891]
Traceback (most recent call last):
  File "/home/pi/Desktop/microblog/venv/lib/python3.7/site-packages/flask/app.py", line 2446, in wsgi_app
    response = self.full_dispatch_request()
  File "/home/pi/Desktop/microblog/venv/lib/python3.7/site-packages/flask/app.py", line 1951, in full_dispatch_request
    rv = self.handle_user_exception(e)
  File "/home/pi/Desktop/microblog/venv/lib/python3.7/site-packages/flask/app.py", line 1820, in handle_user_exception
    reraise(exc_type, exc_value, tb)
  File "/home/pi/Desktop/microblog/venv/lib/python3.7/site-packages/flask/_compat.py", line 39, in reraise
    raise value
  File "/home/pi/Desktop/microblog/venv/lib/python3.7/site-packages/flask/app.py", line 1947, in full_dispatch_request
    rv = self.preprocess_request()
  File "/home/pi/Desktop/microblog/venv/lib/python3.7/site-packages/flask/app.py", line 2241, in preprocess_request
    rv = func()
  File "/home/pi/Desktop/microblog/app/routes.py", line 12, in before_request
    if current_user.is_authenticated:
  File "/home/pi/Desktop/microblog/venv/lib/python3.7/site-packages/werkzeug/local.py", line 347, in __getattr__
    return getattr(self._get_current_object(), name)
  File "/home/pi/Desktop/microblog/venv/lib/python3.7/site-packages/werkzeug/local.py", line 306, in _get_current_object
    return self.__local()
  File "/home/pi/Desktop/microblog/venv/lib/python3.7/site-packages/flask_login/utils.py", line 26, in <lambda>
    current_user = LocalProxy(lambda: _get_user())
  File "/home/pi/Desktop/microblog/venv/lib/python3.7/site-packages/flask_login/utils.py", line 346, in _get_user
    current_app.login_manager._load_user()
  File "/home/pi/Desktop/microblog/venv/lib/python3.7/site-packages/flask_login/login_manager.py", line 318, in _load_user
    user = self._user_callback(user_id)
  File "/home/pi/Desktop/microblog/app/models.py", line 63, in load_user
    return User.query.get(int(id))
  File "/home/pi/Desktop/microblog/venv/lib/python3.7/site-packages/flask_sqlalchemy/__init__.py", line 517, in __get__
    mapper = orm.class_mapper(type)
  File "/home/pi/Desktop/microblog/venv/lib/python3.7/site-packages/sqlalchemy/orm/base.py", line 444, in class_mapper
    mapper = _inspect_mapped_class(class_, configure=configure)
  File "/home/pi/Desktop/microblog/venv/lib/python3.7/site-packages/sqlalchemy/orm/base.py", line 423, in _inspect_mapped_class
    mapper._configure_all()
  File "/home/pi/Desktop/microblog/venv/lib/python3.7/site-packages/sqlalchemy/orm/mapper.py", line 1337, in _configure_all
    configure_mappers()
  File "/home/pi/Desktop/microblog/venv/lib/python3.7/site-packages/sqlalchemy/orm/mapper.py", line 3255, in configure_mappers
    mapper._post_configure_properties()
  File "/home/pi/Desktop/microblog/venv/lib/python3.7/site-packages/sqlalchemy/orm/mapper.py", line 1950, in _post_configure_properties
    prop.init()
  File "/home/pi/Desktop/microblog/venv/lib/python3.7/site-packages/sqlalchemy/orm/interfaces.py", line 196, in init
    self.do_init()
  File "/home/pi/Desktop/microblog/venv/lib/python3.7/site-packages/sqlalchemy/orm/relationships.py", line 1941, in do_init
    super(RelationshipProperty, self).do_init()
  File "/home/pi/Desktop/microblog/venv/lib/python3.7/site-packages/sqlalchemy/orm/interfaces.py", line 572, in do_init
    self.strategy = self._get_strategy(self.strategy_key)
  File "/home/pi/Desktop/microblog/venv/lib/python3.7/site-packages/sqlalchemy/orm/interfaces.py", line 542, in _get_strategy
    cls = self._strategy_lookup(self, *key)
  File "/home/pi/Desktop/microblog/venv/lib/python3.7/site-packages/sqlalchemy/orm/interfaces.py", line 621, in _strategy_lookup
    key,
sqlalchemy.orm.exc.LoaderStrategyException: Can't find strategy (('lazy', 'dyanmic'),) for User.followed
2020-04-02 10:12:34,711 INFO: Microblog startup [in /home/pi/Desktop/microblog/app/__init__.py:44]
2020-04-02 10:49:55,107 INFO: Microblog startup [in /home/pi/Desktop/microblog/app/__init__.py:44]
2020-04-02 10:53:14,589 INFO: Microblog startup [in /home/pi/Desktop/microblog/app/__init__.py:44]
2020-04-04 11:30:53,277 INFO: Microblog startup [in /home/pi/Desktop/microblog/app/__init__.py:44]
2020-04-04 14:54:04,712 INFO: Microblog startup [in /home/pi/Desktop/microblog/app/__init__.py:44]
2020-04-04 14:55:10,742 ERROR: Exception on /index [POST] [in /home/pi/Desktop/microblog/venv/lib/python3.7/site-packages/flask/app.py:1891]
Traceback (most recent call last):
  File "/home/pi/Desktop/microblog/venv/lib/python3.7/site-packages/flask/app.py", line 2446, in wsgi_app
    response = self.full_dispatch_request()
  File "/home/pi/Desktop/microblog/venv/lib/python3.7/site-packages/flask/app.py", line 1951, in full_dispatch_request
    rv = self.handle_user_exception(e)
  File "/home/pi/Desktop/microblog/venv/lib/python3.7/site-packages/flask/app.py", line 1820, in handle_user_exception
    reraise(exc_type, exc_value, tb)
  File "/home/pi/Desktop/microblog/venv/lib/python3.7/site-packages/flask/_compat.py", line 39, in reraise
    raise value
  File "/home/pi/Desktop/microblog/venv/lib/python3.7/site-packages/flask/app.py", line 1949, in full_dispatch_request
    rv = self.dispatch_request()
  File "/home/pi/Desktop/microblog/venv/lib/python3.7/site-packages/flask/app.py", line 1935, in dispatch_request
    return self.view_functions[rule.endpoint](**req.view_args)
  File "/home/pi/Desktop/microblog/venv/lib/python3.7/site-packages/flask_login/utils.py", line 272, in decorated_view
    return func(*args, **kwargs)
  File "/home/pi/Desktop/microblog/app/routes.py", line 27, in index
    return redirect(url_for('index.html'))
  File "/home/pi/Desktop/microblog/venv/lib/python3.7/site-packages/flask/helpers.py", line 370, in url_for
    return appctx.app.handle_url_build_error(error, endpoint, values)
  File "/home/pi/Desktop/microblog/venv/lib/python3.7/site-packages/flask/app.py", line 2215, in handle_url_build_error
    reraise(exc_type, exc_value, tb)
  File "/home/pi/Desktop/microblog/venv/lib/python3.7/site-packages/flask/_compat.py", line 39, in reraise
    raise value
  File "/home/pi/Desktop/microblog/venv/lib/python3.7/site-packages/flask/helpers.py", line 358, in url_for
    endpoint, values, method=method, force_external=external
  File "/home/pi/Desktop/microblog/venv/lib/python3.7/site-packages/werkzeug/routing.py", line 2179, in build
    raise BuildError(endpoint, values, method, self)
werkzeug.routing.BuildError: Could not build url for endpoint 'index.html'. Did you mean 'index' instead?
2020-04-04 14:57:28,399 INFO: Microblog startup [in /home/pi/Desktop/microblog/app/__init__.py:44]
2020-04-04 15:59:11,205 INFO: Microblog startup [in /home/pi/Desktop/microblog/app/__init__.py:44]
2020-04-04 16:03:10,772 INFO: Microblog startup [in /home/pi/Desktop/microblog/app/__init__.py:44]
2020-04-04 19:44:16,000 INFO: Microblog startup [in /home/pi/Desktop/microblog/app/__init__.py:44]
2020-04-04 19:44:38,092 ERROR: Exception on /index [GET] [in /home/pi/Desktop/microblog/venv/lib/python3.7/site-packages/flask/app.py:1891]
Traceback (most recent call last):
  File "/home/pi/Desktop/microblog/venv/lib/python3.7/site-packages/flask/app.py", line 2446, in wsgi_app
    response = self.full_dispatch_request()
  File "/home/pi/Desktop/microblog/venv/lib/python3.7/site-packages/flask/app.py", line 1951, in full_dispatch_request
    rv = self.handle_user_exception(e)
  File "/home/pi/Desktop/microblog/venv/lib/python3.7/site-packages/flask/app.py", line 1820, in handle_user_exception
    reraise(exc_type, exc_value, tb)
  File "/home/pi/Desktop/microblog/venv/lib/python3.7/site-packages/flask/_compat.py", line 39, in reraise
    raise value
  File "/home/pi/Desktop/microblog/venv/lib/python3.7/site-packages/flask/app.py", line 1949, in full_dispatch_request
    rv = self.dispatch_request()
  File "/home/pi/Desktop/microblog/venv/lib/python3.7/site-packages/flask/app.py", line 1935, in dispatch_request
    return self.view_functions[rule.endpoint](**req.view_args)
  File "/home/pi/Desktop/microblog/venv/lib/python3.7/site-packages/flask_login/utils.py", line 272, in decorated_view
    return func(*args, **kwargs)
  File "/home/pi/Desktop/microblog/app/routes.py", line 28, in index
    page = request.args.get('page', 1, type-int)
TypeError: unsupported operand type(s) for -: 'type' and 'type'
2020-04-04 19:45:33,466 INFO: Microblog startup [in /home/pi/Desktop/microblog/app/__init__.py:44]
