2020-04-11 14:40:33,293 ERROR: Exception on /index [GET] [in /home/pi/Desktop/microblog/venv/lib/python3.7/site-packages/flask/app.py:1891]
Traceback (most recent call last):
  File "/home/pi/Desktop/microblog/venv/lib/python3.7/site-packages/flask/app.py", line 2446, in wsgi_app
    response = self.full_dispatch_request()
  File "/home/pi/Desktop/microblog/venv/lib/python3.7/site-packages/flask/app.py", line 1951, in full_dispatch_request
    rv = self.handle_user_exception(e)
  File "/home/pi/Desktop/microblog/venv/lib/python3.7/site-packages/flask/app.py", line 1820, in handle_user_exception
    reraise(exc_type, exc_value, tb)
  File "/home/pi/Desktop/microblog/venv/lib/python3.7/site-packages/flask/_compat.py", line 39, in reraise
    raise value
  File "/home/pi/Desktop/microblog/venv/lib/python3.7/site-packages/flask/app.py", line 1949, in full_dispatch_request
    rv = self.dispatch_request()
  File "/home/pi/Desktop/microblog/venv/lib/python3.7/site-packages/flask/app.py", line 1935, in dispatch_request
    return self.view_functions[rule.endpoint](**req.view_args)
  File "/home/pi/Desktop/microblog/venv/lib/python3.7/site-packages/flask_login/utils.py", line 272, in decorated_view
    return func(*args, **kwargs)
  File "/home/pi/Desktop/microblog/app/routes.py", line 39, in index
    prev_url=prev_url)
  File "/home/pi/Desktop/microblog/venv/lib/python3.7/site-packages/flask/templating.py", line 140, in render_template
    ctx.app,
  File "/home/pi/Desktop/microblog/venv/lib/python3.7/site-packages/flask/templating.py", line 120, in _render
    rv = template.render(context)
  File "/home/pi/Desktop/microblog/venv/lib/python3.7/site-packages/jinja2/environment.py", line 1090, in render
    self.environment.handle_exception()
  File "/home/pi/Desktop/microblog/venv/lib/python3.7/site-packages/jinja2/environment.py", line 832, in handle_exception
    reraise(*rewrite_traceback_stack(source=source))
  File "/home/pi/Desktop/microblog/venv/lib/python3.7/site-packages/jinja2/_compat.py", line 28, in reraise
    raise value.with_traceback(tb)
  File "/home/pi/Desktop/microblog/app/templates/index.html", line 2, in top-level template code
    {% import 'bootstrap/wtf.html' as wtf %}
  File "/home/pi/Desktop/microblog/app/templates/base.html", line 1, in top-level template code
    {% extends 'bootstrap/base.html' %}
  File "/home/pi/Desktop/microblog/venv/lib/python3.7/site-packages/flask_bootstrap/templates/bootstrap/base.html", line 1, in top-level template code
    {% block doc -%}
  File "/home/pi/Desktop/microblog/venv/lib/python3.7/site-packages/flask_bootstrap/templates/bootstrap/base.html", line 3, in block "doc"
    <html{% block html_attribs %}{% endblock html_attribs %}>
  File "/home/pi/Desktop/microblog/venv/lib/python3.7/site-packages/flask_bootstrap/templates/bootstrap/base.html", line 11, in block "html"
    {%- endblock metas %}
  File "/home/pi/Desktop/microblog/venv/lib/python3.7/site-packages/flask_bootstrap/templates/bootstrap/base.html", line 13, in block "body"
    {%- block styles %}
  File "/home/pi/Desktop/microblog/app/templates/base.html", line 48, in block "content"
    {% block app_content %}{% endblock %}
  File "/home/pi/Desktop/microblog/app/templates/index.html", line 11, in block "app_content"
    {% include '_post.html' %}
  File "/home/pi/Desktop/microblog/app/templates/_post.html", line 4, in top-level template code
    <a href="{{ url_for('user', uername=post.author.username) }}">
  File "/home/pi/Desktop/microblog/venv/lib/python3.7/site-packages/flask/helpers.py", line 370, in url_for
    return appctx.app.handle_url_build_error(error, endpoint, values)
  File "/home/pi/Desktop/microblog/venv/lib/python3.7/site-packages/flask/app.py", line 2215, in handle_url_build_error
    reraise(exc_type, exc_value, tb)
  File "/home/pi/Desktop/microblog/venv/lib/python3.7/site-packages/flask/_compat.py", line 39, in reraise
    raise value
  File "/home/pi/Desktop/microblog/venv/lib/python3.7/site-packages/flask/helpers.py", line 358, in url_for
    endpoint, values, method=method, force_external=external
  File "/home/pi/Desktop/microblog/venv/lib/python3.7/site-packages/werkzeug/routing.py", line 2179, in build
    raise BuildError(endpoint, values, method, self)
werkzeug.routing.BuildError: Could not build url for endpoint 'user' with values ['uername']. Did you forget to specify values ['username']?
2020-04-11 14:40:35,261 ERROR: Exception on /explore [GET] [in /home/pi/Desktop/microblog/venv/lib/python3.7/site-packages/flask/app.py:1891]
Traceback (most recent call last):
  File "/home/pi/Desktop/microblog/venv/lib/python3.7/site-packages/flask/app.py", line 2446, in wsgi_app
    response = self.full_dispatch_request()
  File "/home/pi/Desktop/microblog/venv/lib/python3.7/site-packages/flask/app.py", line 1951, in full_dispatch_request
    rv = self.handle_user_exception(e)
  File "/home/pi/Desktop/microblog/venv/lib/python3.7/site-packages/flask/app.py", line 1820, in handle_user_exception
    reraise(exc_type, exc_value, tb)
  File "/home/pi/Desktop/microblog/venv/lib/python3.7/site-packages/flask/_compat.py", line 39, in reraise
    raise value
  File "/home/pi/Desktop/microblog/venv/lib/python3.7/site-packages/flask/app.py", line 1949, in full_dispatch_request
    rv = self.dispatch_request()
  File "/home/pi/Desktop/microblog/venv/lib/python3.7/site-packages/flask/app.py", line 1935, in dispatch_request
    return self.view_functions[rule.endpoint](**req.view_args)
  File "/home/pi/Desktop/microblog/venv/lib/python3.7/site-packages/flask_login/utils.py", line 272, in decorated_view
    return func(*args, **kwargs)
  File "/home/pi/Desktop/microblog/app/routes.py", line 53, in explore
    next_url=next_url, prev_url=prev_url)
  File "/home/pi/Desktop/microblog/venv/lib/python3.7/site-packages/flask/templating.py", line 140, in render_template
    ctx.app,
  File "/home/pi/Desktop/microblog/venv/lib/python3.7/site-packages/flask/templating.py", line 120, in _render
    rv = template.render(context)
  File "/home/pi/Desktop/microblog/venv/lib/python3.7/site-packages/jinja2/environment.py", line 1090, in render
    self.environment.handle_exception()
  File "/home/pi/Desktop/microblog/venv/lib/python3.7/site-packages/jinja2/environment.py", line 832, in handle_exception
    reraise(*rewrite_traceback_stack(source=source))
  File "/home/pi/Desktop/microblog/venv/lib/python3.7/site-packages/jinja2/_compat.py", line 28, in reraise
    raise value.with_traceback(tb)
  File "/home/pi/Desktop/microblog/app/templates/index.html", line 2, in top-level template code
    {% import 'bootstrap/wtf.html' as wtf %}
  File "/home/pi/Desktop/microblog/app/templates/base.html", line 1, in top-level template code
    {% extends 'bootstrap/base.html' %}
  File "/home/pi/Desktop/microblog/venv/lib/python3.7/site-packages/flask_bootstrap/templates/bootstrap/base.html", line 1, in top-level template code
    {% block doc -%}
  File "/home/pi/Desktop/microblog/venv/lib/python3.7/site-packages/flask_bootstrap/templates/bootstrap/base.html", line 3, in block "doc"
    <html{% block html_attribs %}{% endblock html_attribs %}>
  File "/home/pi/Desktop/microblog/venv/lib/python3.7/site-packages/flask_bootstrap/templates/bootstrap/base.html", line 11, in block "html"
    {%- endblock metas %}
  File "/home/pi/Desktop/microblog/venv/lib/python3.7/site-packages/flask_bootstrap/templates/bootstrap/base.html", line 13, in block "body"
    {%- block styles %}
  File "/home/pi/Desktop/microblog/app/templates/base.html", line 48, in block "content"
    {% block app_content %}{% endblock %}
  File "/home/pi/Desktop/microblog/app/templates/index.html", line 11, in block "app_content"
    {% include '_post.html' %}
  File "/home/pi/Desktop/microblog/app/templates/_post.html", line 4, in top-level template code
    <a href="{{ url_for('user', uername=post.author.username) }}">
  File "/home/pi/Desktop/microblog/venv/lib/python3.7/site-packages/flask/helpers.py", line 370, in url_for
    return appctx.app.handle_url_build_error(error, endpoint, values)
  File "/home/pi/Desktop/microblog/venv/lib/python3.7/site-packages/flask/app.py", line 2215, in handle_url_build_error
    reraise(exc_type, exc_value, tb)
  File "/home/pi/Desktop/microblog/venv/lib/python3.7/site-packages/flask/_compat.py", line 39, in reraise
    raise value
  File "/home/pi/Desktop/microblog/venv/lib/python3.7/site-packages/flask/helpers.py", line 358, in url_for
    endpoint, values, method=method, force_external=external
  File "/home/pi/Desktop/microblog/venv/lib/python3.7/site-packages/werkzeug/routing.py", line 2179, in build
    raise BuildError(endpoint, values, method, self)
werkzeug.routing.BuildError: Could not build url for endpoint 'user' with values ['uername']. Did you forget to specify values ['username']?
2020-04-11 14:42:29,806 INFO: Microblog startup [in /home/pi/Desktop/microblog/app/__init__.py:49]
