2020-03-31 12:23:17,139 INFO: Microblog startup [in /home/pi/Desktop/microblog/app/__init__.py:44]
2020-04-01 10:06:23,834 INFO: Microblog startup [in /home/pi/Desktop/microblog/app/__init__.py:44]
2020-04-01 10:13:02,899 INFO: Microblog startup [in /home/pi/Desktop/microblog/app/__init__.py:44]
2020-04-01 10:13:19,597 ERROR: Exception on /user/john [GET] [in /home/pi/Desktop/microblog/venv/lib/python3.7/site-packages/flask/app.py:1891]
Traceback (most recent call last):
  File "/home/pi/Desktop/microblog/venv/lib/python3.7/site-packages/flask/app.py", line 2446, in wsgi_app
    response = self.full_dispatch_request()
  File "/home/pi/Desktop/microblog/venv/lib/python3.7/site-packages/flask/app.py", line 1951, in full_dispatch_request
    rv = self.handle_user_exception(e)
  File "/home/pi/Desktop/microblog/venv/lib/python3.7/site-packages/flask/app.py", line 1820, in handle_user_exception
    reraise(exc_type, exc_value, tb)
  File "/home/pi/Desktop/microblog/venv/lib/python3.7/site-packages/flask/_compat.py", line 39, in reraise
    raise value
  File "/home/pi/Desktop/microblog/venv/lib/python3.7/site-packages/flask/app.py", line 1949, in full_dispatch_request
    rv = self.dispatch_request()
  File "/home/pi/Desktop/microblog/venv/lib/python3.7/site-packages/flask/app.py", line 1935, in dispatch_request
    return self.view_functions[rule.endpoint](**req.view_args)
  File "/home/pi/Desktop/microblog/venv/lib/python3.7/site-packages/flask_login/utils.py", line 272, in decorated_view
    return func(*args, **kwargs)
  File "/home/pi/Desktop/microblog/app/routes.py", line 77, in user
    return render_template('user.html', user=user, posts=posts)
  File "/home/pi/Desktop/microblog/venv/lib/python3.7/site-packages/flask/templating.py", line 138, in render_template
    ctx.app.jinja_env.get_or_select_template(template_name_or_list),
  File "/home/pi/Desktop/microblog/venv/lib/python3.7/site-packages/jinja2/environment.py", line 930, in get_or_select_template
    return self.get_template(template_name_or_list, parent, globals)
  File "/home/pi/Desktop/microblog/venv/lib/python3.7/site-packages/jinja2/environment.py", line 883, in get_template
    return self._load_template(name, self.make_globals(globals))
  File "/home/pi/Desktop/microblog/venv/lib/python3.7/site-packages/jinja2/environment.py", line 857, in _load_template
    template = self.loader.load(self, name, globals)
  File "/home/pi/Desktop/microblog/venv/lib/python3.7/site-packages/jinja2/loaders.py", line 129, in load
    code = environment.compile(source, name, filename)
  File "/home/pi/Desktop/microblog/venv/lib/python3.7/site-packages/jinja2/environment.py", line 638, in compile
    self.handle_exception(source=source_hint)
  File "/home/pi/Desktop/microblog/venv/lib/python3.7/site-packages/jinja2/environment.py", line 832, in handle_exception
    reraise(*rewrite_traceback_stack(source=source))
  File "/home/pi/Desktop/microblog/venv/lib/python3.7/site-packages/jinja2/_compat.py", line 28, in reraise
    raise value.with_traceback(tb)
  File "/home/pi/Desktop/microblog/app/templates/user.html", line 17, in template
    <p><a href="{{ url_for('unfollow', username=user.username) }}">Unfollow</a></p>
jinja2.exceptions.TemplateSyntaxError: expected token ',', got 'unfollow'
2020-04-01 10:14:06,273 ERROR: Exception on /user/susan [GET] [in /home/pi/Desktop/microblog/venv/lib/python3.7/site-packages/flask/app.py:1891]
Traceback (most recent call last):
  File "/home/pi/Desktop/microblog/venv/lib/python3.7/site-packages/flask/app.py", line 2446, in wsgi_app
    response = self.full_dispatch_request()
  File "/home/pi/Desktop/microblog/venv/lib/python3.7/site-packages/flask/app.py", line 1951, in full_dispatch_request
    rv = self.handle_user_exception(e)
  File "/home/pi/Desktop/microblog/venv/lib/python3.7/site-packages/flask/app.py", line 1820, in handle_user_exception
    reraise(exc_type, exc_value, tb)
  File "/home/pi/Desktop/microblog/venv/lib/python3.7/site-packages/flask/_compat.py", line 39, in reraise
    raise value
  File "/home/pi/Desktop/microblog/venv/lib/python3.7/site-packages/flask/app.py", line 1949, in full_dispatch_request
    rv = self.dispatch_request()
  File "/home/pi/Desktop/microblog/venv/lib/python3.7/site-packages/flask/app.py", line 1935, in dispatch_request
    return self.view_functions[rule.endpoint](**req.view_args)
  File "/home/pi/Desktop/microblog/venv/lib/python3.7/site-packages/flask_login/utils.py", line 272, in decorated_view
    return func(*args, **kwargs)
  File "/home/pi/Desktop/microblog/app/routes.py", line 77, in user
    return render_template('user.html', user=user, posts=posts)
  File "/home/pi/Desktop/microblog/venv/lib/python3.7/site-packages/flask/templating.py", line 138, in render_template
    ctx.app.jinja_env.get_or_select_template(template_name_or_list),
  File "/home/pi/Desktop/microblog/venv/lib/python3.7/site-packages/jinja2/environment.py", line 930, in get_or_select_template
    return self.get_template(template_name_or_list, parent, globals)
  File "/home/pi/Desktop/microblog/venv/lib/python3.7/site-packages/jinja2/environment.py", line 883, in get_template
    return self._load_template(name, self.make_globals(globals))
  File "/home/pi/Desktop/microblog/venv/lib/python3.7/site-packages/jinja2/environment.py", line 857, in _load_template
    template = self.loader.load(self, name, globals)
  File "/home/pi/Desktop/microblog/venv/lib/python3.7/site-packages/jinja2/loaders.py", line 129, in load
    code = environment.compile(source, name, filename)
  File "/home/pi/Desktop/microblog/venv/lib/python3.7/site-packages/jinja2/environment.py", line 638, in compile
    self.handle_exception(source=source_hint)
  File "/home/pi/Desktop/microblog/venv/lib/python3.7/site-packages/jinja2/environment.py", line 832, in handle_exception
    reraise(*rewrite_traceback_stack(source=source))
  File "/home/pi/Desktop/microblog/venv/lib/python3.7/site-packages/jinja2/_compat.py", line 28, in reraise
    raise value.with_traceback(tb)
  File "/home/pi/Desktop/microblog/app/templates/user.html", line 17, in template
    <p><a href="{{ url_for('unfollow', username=user.username) }}">Unfollow</a></p>
jinja2.exceptions.TemplateSyntaxError: expected token ',', got 'unfollow'
2020-04-01 10:15:56,340 INFO: Microblog startup [in /home/pi/Desktop/microblog/app/__init__.py:44]
2020-04-01 10:16:02,158 ERROR: Exception on /user/susan [GET] [in /home/pi/Desktop/microblog/venv/lib/python3.7/site-packages/flask/app.py:1891]
Traceback (most recent call last):
  File "/home/pi/Desktop/microblog/venv/lib/python3.7/site-packages/flask/app.py", line 2446, in wsgi_app
    response = self.full_dispatch_request()
  File "/home/pi/Desktop/microblog/venv/lib/python3.7/site-packages/flask/app.py", line 1951, in full_dispatch_request
    rv = self.handle_user_exception(e)
  File "/home/pi/Desktop/microblog/venv/lib/python3.7/site-packages/flask/app.py", line 1820, in handle_user_exception
    reraise(exc_type, exc_value, tb)
  File "/home/pi/Desktop/microblog/venv/lib/python3.7/site-packages/flask/_compat.py", line 39, in reraise
    raise value
  File "/home/pi/Desktop/microblog/venv/lib/python3.7/site-packages/flask/app.py", line 1949, in full_dispatch_request
    rv = self.dispatch_request()
  File "/home/pi/Desktop/microblog/venv/lib/python3.7/site-packages/flask/app.py", line 1935, in dispatch_request
    return self.view_functions[rule.endpoint](**req.view_args)
  File "/home/pi/Desktop/microblog/venv/lib/python3.7/site-packages/flask_login/utils.py", line 272, in decorated_view
    return func(*args, **kwargs)
  File "/home/pi/Desktop/microblog/app/routes.py", line 77, in user
    return render_template('user.html', user=user, posts=posts)
  File "/home/pi/Desktop/microblog/venv/lib/python3.7/site-packages/flask/templating.py", line 140, in render_template
    ctx.app,
  File "/home/pi/Desktop/microblog/venv/lib/python3.7/site-packages/flask/templating.py", line 120, in _render
    rv = template.render(context)
  File "/home/pi/Desktop/microblog/venv/lib/python3.7/site-packages/jinja2/environment.py", line 1090, in render
    self.environment.handle_exception()
  File "/home/pi/Desktop/microblog/venv/lib/python3.7/site-packages/jinja2/environment.py", line 832, in handle_exception
    reraise(*rewrite_traceback_stack(source=source))
  File "/home/pi/Desktop/microblog/venv/lib/python3.7/site-packages/jinja2/_compat.py", line 28, in reraise
    raise value.with_traceback(tb)
  File "/home/pi/Desktop/microblog/app/templates/user.html", line 1, in top-level template code
    {% extends "base.html" %}
  File "/home/pi/Desktop/microblog/app/templates/base.html", line 30, in top-level template code
    {% block content %}{% endblock %}
  File "/home/pi/Desktop/microblog/app/templates/user.html", line 11, in block "content"
    <p>{{ user.followers.count() }} followers, {{ user.followed.count() }} following.</p>
  File "/home/pi/Desktop/microblog/venv/lib/python3.7/site-packages/jinja2/environment.py", line 471, in getattr
    return getattr(obj, attribute)
jinja2.exceptions.UndefinedError: 'app.models.User object' has no attribute 'followers'
2020-04-01 10:40:29,202 INFO: Microblog startup [in /home/pi/Desktop/microblog/app/__init__.py:44]
2020-04-01 10:40:47,172 INFO: Microblog startup [in /home/pi/Desktop/microblog/app/__init__.py:44]
2020-04-01 10:41:51,247 INFO: Microblog startup [in /home/pi/Desktop/microblog/app/__init__.py:44]
